Workbook
Name UPDATE: HCLTech!$E$1
Name UPDATE: Infosys!$E$1
Name UPDATE: TCS!$E$1
Name UPDATE: TechM!$E$1
Name UPDATE: Wipro!$E$1
Name UPDATE: #REF!

Sheet Summary
A1: Company | B1: Year | C1: Revenue | D1: Net Profit | E1: Total Assets | F1: Equity Capital | G1: Reserves | H1: Shareholders' Equity | I1: Borrowings | J1: EPS | K1: ROE | L1: ROCE
A2: TCS | B2: 42825 | C2: =INDEX(TCS!$B:$K,MATCH("Sales",TCS!$A:$A,0),MATCH($B2,TCS!$B$16:$K$16,0)) -> 117966 | D2: =INDEX(TCS!$B:$K,MATCH("Net profit",TCS!$A:$A,0),MATCH($B2,TCS!$B$16:$K$16,0)) -> 26289 | E2: =TCS!B66 -> 102333 | F2: =INDEX(TCS!$B:$K,MATCH("Equity Share Capital",TCS!$A:$A,0),MATCH($B2,TCS!$B$16:$K$16,0)) -> 197 | G2: =INDEX(TCS!$B:$K,MATCH("Reserves",TCS!$A:$A,0),MATCH($B2,TCS!$B$16:$K$16,0)) -> 86017 | H2: =F2+G2 -> 86214 | I2: =INDEX(TCS!$B:$K,MATCH("Borrowings",TCS!$A:$A,0),MATCH($B2,TCS!$B$16:$K$16,0)) -> 289 | J2: =INDEX(TCS!$B:$K,MATCH("EPS",TCS!$A:$A,0),MATCH($B2,TCS!$B$16:$K$16,0)) -> 66.708112 | K2: =INDEX(TCS!$B:$K,MATCH("Return on Equity",TCS!$A:$A,0),MATCH($B2,TCS!$B$16:$K$16,0)) -> 0.30492727
A3: TCS | B3: 43190 | C3: =INDEX(TCS!$B:$K,MATCH("Sales",TCS!$A:$A,0),MATCH($B3,TCS!$B$16:$K$16,0)) -> 123104 | D3: =INDEX(TCS!$B:$K,MATCH("Net profit",TCS!$A:$A,0),MATCH($B3,TCS!$B$16:$K$16,0)) -> 25826 | E3: =TCS!C66 -> 105126 | F3: =INDEX(TCS!$B:$K,MATCH("Equity Share Capital",TCS!$A:$A,0),MATCH($B3,TCS!$B$16:$K$16,0)) -> 191 | G3: =INDEX(TCS!$B:$K,MATCH("Reserves",TCS!$A:$A,0),MATCH($B3,TCS!$B$16:$K$16,0)) -> 84937 | H3: =F3+G3 -> 85128 | I3: =INDEX(TCS!$B:$K,MATCH("Borrowings",TCS!$A:$A,0),MATCH($B3,TCS!$B$16:$K$16,0)) -> 247 | J3: =INDEX(TCS!$B:$K,MATCH("EPS",TCS!$A:$A,0),MATCH($B3,TCS!$B$16:$K$16,0)) -> 67.455467 | K3: =INDEX(TCS!$B:$K,MATCH("Return on Equity",TCS!$A:$A,0),MATCH($B3,TCS!$B$16:$K$16,0)) -> 0.30337844 | L3: =INDEX(TCS!$B:$K,MATCH("Return on Capital Emp",TCS!$A:$A,0),MATCH($B3,TCS!$B$16:$K$16,0)) -> 0.39730507
A4: TCS | B4: 43555 | C4: =INDEX(TCS!$B:$K,MATCH("Sales",TCS!$A:$A,0),MATCH($B4,TCS!$B$16:$K$16,0)) -> 146463 | D4: =INDEX(TCS!$B:$K,MATCH("Net profit",TCS!$A:$A,0),MATCH($B4,TCS!$B$16:$K$16,0)) -> 31472 | E4: =TCS!D66 -> 113901 | F4: =INDEX(TCS!$B:$K,MATCH("Equity Share Capital",TCS!$A:$A,0),MATCH($B4,TCS!$B$16:$K$16,0)) -> 375 | G4: =INDEX(TCS!$B:$K,MATCH("Reserves",TCS!$A:$A,0),MATCH($B4,TCS!$B$16:$K$16,0)) -> 89071 | H4: =F4+G4 -> 89446 | I4: =INDEX(TCS!$B:$K,MATCH("Borrowings",TCS!$A:$A,0),MATCH($B4,TCS!$B$16:$K$16,0)) -> 62 | J4: =INDEX(TCS!$B:$K,MATCH("EPS",TCS!$A:$A,0),MATCH($B4,TCS!$B$16:$K$16,0)) -> 83.871655 | K4: =INDEX(TCS!$B:$K,MATCH("Return on Equity",TCS!$A:$A,0),MATCH($B4,TCS!$B$16:$K$16,0)) -> 0.35185475 | L4: =INDEX(TCS!$B:$K,MATCH("Return on Capital Emp",TCS!$A:$A,0),MATCH($B4,TCS!$B$16:$K$16,0)) -> 0.47758787
A5: TCS | B5: 43921 | C5: =INDEX(TCS!$B:$K,MATCH("Sales",TCS!$A:$A,0),MATCH($B5,TCS!$B$16:$K$16,0)) -> 156949 | D5: =INDEX(TCS!$B:$K,MATCH("Net profit",TCS!$A:$A,0),MATCH($B5,TCS!$B$16:$K$16,0)) -> 32340 | E5: =TCS!E66 -> 120127 | F5: =INDEX(TCS!$B:$K,MATCH("Equity Share Capital",TCS!$A:$A,0),MATCH($B5,TCS!$B$16:$K$16,0)) -> 375 | G5: =INDEX(TCS!$B:$K,MATCH("Reserves",TCS!$A:$A,0),MATCH($B5,TCS!$B$16:$K$16,0)) -> 83751 | H5: =F5+G5 -> 84126 | I5: =INDEX(TCS!$B:$K,MATCH("Borrowings",TCS!$A:$A,0),MATCH($B5,TCS!$B$16:$K$16,0)) -> 8174 | J5: =INDEX(TCS!$B:$K,MATCH("EPS",TCS!$A:$A,0),MATCH($B5,TCS!$B$16:$K$16,0)) -> 86.184842 | K5: =INDEX(TCS!$B:$K,MATCH("Return on Equity",TCS!$A:$A,0),MATCH($B5,TCS!$B$16:$K$16,0)) -> 0.38442336 | L5: =INDEX(TCS!$B:$K,MATCH("Return on Capital Emp",TCS!$A:$A,0),MATCH($B5,TCS!$B$16:$K$16,0)) -> 0.4749186
A6: TCS | B6: 44286 | C6: =INDEX(TCS!$B:$K,MATCH("Sales",TCS!$A:$A,0),MATCH($B6,TCS!$B$16:$K$16,0)) -> 164177 | D6: =INDEX(TCS!$B:$K,MATCH("Net profit",TCS!$A:$A,0),MATCH($B6,TCS!$B$16:$K$16,0)) -> 32430 | E6: =TCS!F66 -> 129992 | F6: =INDEX(TCS!$B:$K,MATCH("Equity Share Capital",TCS!$A:$A,0),MATCH($B6,TCS!$B$16:$K$16,0)) -> 370 | G6: =INDEX(TCS!$B:$K,MATCH("Reserves",TCS!$A:$A,0),MATCH($B6,TCS!$B$16:$K$16,0)) -> 86063 | H6: =F6+G6 -> 86433 | I6: =INDEX(TCS!$B:$K,MATCH("Borrowings",TCS!$A:$A,0),MATCH($B6,TCS!$B$16:$K$16,0)) -> 7795 | J6: =INDEX(TCS!$B:$K,MATCH("EPS",TCS!$A:$A,0),MATCH($B6,TCS!$B$16:$K$16,0)) -> 87.669974 | K6: =INDEX(TCS!$B:$K,MATCH("Return on Equity",TCS!$A:$A,0),MATCH($B6,TCS!$B$16:$K$16,0)) -> 0.37520392 | L6: =INDEX(TCS!$B:$K,MATCH("Return on Capital Emp",TCS!$A:$A,0),MATCH($B6,TCS!$B$16:$K$16,0)) -> 0.47603577
A7: TCS | B7: 44651 | C7: =INDEX(TCS!$B:$K,MATCH("Sales",TCS!$A:$A,0),MATCH($B7,TCS!$B$16:$K$16,0)) -> 191754 | D7: =INDEX(TCS!$B:$K,MATCH("Net profit",TCS!$A:$A,0),MATCH($B7,TCS!$B$16:$K$16,0)) -> 38327 | E7: =TCS!G66 -> 140924 | F7: =INDEX(TCS!$B:$K,MATCH("Equity Share Capital",TCS!$A:$A,0),MATCH($B7,TCS!$B$16:$K$16,0)) -> 366 | G7: =INDEX(TCS!$B:$K,MATCH("Reserves",TCS!$A:$A,0),MATCH($B7,TCS!$B$16:$K$16,0)) -> 88773 | H7: =F7+G7 -> 89139 | I7: =INDEX(TCS!$B:$K,MATCH("Borrowings",TCS!$A:$A,0),MATCH($B7,TCS!$B$16:$K$16,0)) -> 7818 | J7: =INDEX(TCS!$B:$K,MATCH("EPS",TCS!$A:$A,0),MATCH($B7,TCS!$B$16:$K$16,0)) -> 104.74434 | K7: =INDEX(TCS!$B:$K,MATCH("Return on Equity",TCS!$A:$A,0),MATCH($B7,TCS!$B$16:$K$16,0)) -> 0.42996892 | L7: =INDEX(TCS!$B:$K,MATCH("Return on Capital Emp",TCS!$A:$A,0),MATCH($B7,TCS!$B$16:$K$16,0)) -> 0.5489029
A8: TCS | B8: 45016 | C8: =INDEX(TCS!$B:$K,MATCH("Sales",TCS!$A:$A,0),MATCH($B8,TCS!$B$16:$K$16,0)) -> 225458 | D8: =INDEX(TCS!$B:$K,MATCH("Net profit",TCS!$A:$A,0),MATCH($B8,TCS!$B$16:$K$16,0)) -> 42147 | E8: =TCS!H66 -> 142859 | F8: =INDEX(TCS!$B:$K,MATCH("Equity Share Capital",TCS!$A:$A,0),MATCH($B8,TCS!$B$16:$K$16,0)) -> 366 | G8: =INDEX(TCS!$B:$K,MATCH("Reserves",TCS!$A:$A,0),MATCH($B8,TCS!$B$16:$K$16,0)) -> 90058 | H8: =F8+G8 -> 90424 | I8: =INDEX(TCS!$B:$K,MATCH("Borrowings",TCS!$A:$A,0),MATCH($B8,TCS!$B$16:$K$16,0)) -> 7688 | J8: =INDEX(TCS!$B:$K,MATCH("EPS",TCS!$A:$A,0),MATCH($B8,TCS!$B$16:$K$16,0)) -> 115.18406 | K8: =INDEX(TCS!$B:$K,MATCH("Return on Equity",TCS!$A:$A,0),MATCH($B8,TCS!$B$16:$K$16,0)) -> 0.46610413 | L8: =INDEX(TCS!$B:$K,MATCH("Return on Capital Emp",TCS!$A:$A,0),MATCH($B8,TCS!$B$16:$K$16,0)) -> 0.591442
A9: TCS | B9: 45382 | C9: =INDEX(TCS!$B:$K,MATCH("Sales",TCS!$A:$A,0),MATCH($B9,TCS!$B$16:$K$16,0)) -> 240893 | D9: =INDEX(TCS!$B:$K,MATCH("Net profit",TCS!$A:$A,0),MATCH($B9,TCS!$B$16:$K$16,0)) -> 45908 | E9: =TCS!I66 -> 145472 | F9: =INDEX(TCS!$B:$K,MATCH("Equity Share Capital",TCS!$A:$A,0),MATCH($B9,TCS!$B$16:$K$16,0)) -> 362 | G9: =INDEX(TCS!$B:$K,MATCH("Reserves",TCS!$A:$A,0),MATCH($B9,TCS!$B$16:$K$16,0)) -> 90127 | H9: =F9+G9 -> 90489 | I9: =INDEX(TCS!$B:$K,MATCH("Borrowings",TCS!$A:$A,0),MATCH($B9,TCS!$B$16:$K$16,0)) -> 8021 | J9: =INDEX(TCS!$B:$K,MATCH("EPS",TCS!$A:$A,0),MATCH($B9,TCS!$B$16:$K$16,0)) -> 126.88428 | K9: =INDEX(TCS!$B:$K,MATCH("Return on Equity",TCS!$A:$A,0),MATCH($B9,TCS!$B$16:$K$16,0)) -> 0.50733238 | L9: =INDEX(TCS!$B:$K,MATCH("Return on Capital Emp",TCS!$A:$A,0),MATCH($B9,TCS!$B$16:$K$16,0)) -> 0.63853485
A10: TCS | B10: 45747 | C10: =INDEX(TCS!$B:$K,MATCH("Sales",TCS!$A:$A,0),MATCH($B10,TCS!$B$16:$K$16,0)) -> 255324 | D10: =INDEX(TCS!$B:$K,MATCH("Net profit",TCS!$A:$A,0),MATCH($B10,TCS!$B$16:$K$16,0)) -> 48553 | E10: =TCS!J66 -> 158649 | F10: =INDEX(TCS!$B:$K,MATCH("Equity Share Capital",TCS!$A:$A,0),MATCH($B10,TCS!$B$16:$K$16,0)) -> 362 | G10: =INDEX(TCS!$B:$K,MATCH("Reserves",TCS!$A:$A,0),MATCH($B10,TCS!$B$16:$K$16,0)) -> 94394 | H10: =F10+G10 -> 94756 | I10: =INDEX(TCS!$B:$K,MATCH("Borrowings",TCS!$A:$A,0),MATCH($B10,TCS!$B$16:$K$16,0)) -> 9392 | J10: =INDEX(TCS!$B:$K,MATCH("EPS",TCS!$A:$A,0),MATCH($B10,TCS!$B$16:$K$16,0)) -> 134.19474 | K10: =INDEX(TCS!$B:$K,MATCH("Return on Equity",TCS!$A:$A,0),MATCH($B10,TCS!$B$16:$K$16,0)) -> 0.51240027 | L10: =INDEX(TCS!$B:$K,MATCH("Return on Capital Emp",TCS!$A:$A,0),MATCH($B10,TCS!$B$16:$K$16,0)) -> 0.65259699
A11: TCS | B11: 46112 | C11: =INDEX(TCS!$B:$K,MATCH("Sales",TCS!$A:$A,0),MATCH($B11,TCS!$B$16:$K$16,0)) -> 267021 | D11: =INDEX(TCS!$B:$K,MATCH("Net profit",TCS!$A:$A,0),MATCH($B11,TCS!$B$16:$K$16,0)) -> 49210 | E11: =TCS!K66 -> 181167 | F11: =INDEX(TCS!$B:$K,MATCH("Equity Share Capital",TCS!$A:$A,0),MATCH($B11,TCS!$B$16:$K$16,0)) -> 362 | G11: =INDEX(TCS!$B:$K,MATCH("Reserves",TCS!$A:$A,0),MATCH($B11,TCS!$B$16:$K$16,0)) -> 106878 | H11: =F11+G11 -> 107240 | I11: =INDEX(TCS!$B:$K,MATCH("Borrowings",TCS!$A:$A,0),MATCH($B11,TCS!$B$16:$K$16,0)) -> 11283 | J11: =INDEX(TCS!$B:$K,MATCH("EPS",TCS!$A:$A,0),MATCH($B11,TCS!$B$16:$K$16,0)) -> 136.01061 | K11: =INDEX(TCS!$B:$K,MATCH("Return on Equity",TCS!$A:$A,0),MATCH($B11,TCS!$B$16:$K$16,0)) -> 0.45887728 | L11: =INDEX(TCS!$B:$K,MATCH("Return on Capital Emp",TCS!$A:$A,0),MATCH($B11,TCS!$B$16:$K$16,0)) -> 0.59921588
A12: Infosys | B12: 42825 | C12: =INDEX(Infosys!$B:$K,MATCH("Sales",Infosys!$A:$A,0),MATCH($B2,Infosys!$B$16:$K$16,0)) -> 68484 | D12: =INDEX(Infosys!$B:$K,MATCH("Net profit",Infosys!$A:$A,0),MATCH($B2,Infosys!$B$16:$K$16,0)) -> 14353 | E12: =Infosys!B66 -> 83148 | F12: =INDEX(Infosys!$B:$K,MATCH("Equity Share Capital",Infosys!$A:$A,0),MATCH($B2,Infosys!$B$16:$K$16,0)) -> 1144 | G12: =INDEX(Infosys!$B:$K,MATCH("Reserves",Infosys!$A:$A,0),MATCH($B2,Infosys!$B$16:$K$16,0)) -> 67838 | H12: =F12+G12 -> 68982 | J12: =INDEX(Infosys!$B:$K,MATCH("EPS",Infosys!$A:$A,0),MATCH($B2,Infosys!$B$16:$K$16,0)) -> 31.243606 | K12: =INDEX(Infosys!$B:$K,MATCH("Return on Equity",Infosys!$A:$A,0),MATCH($B2,Infosys!$B$16:$K$16,0)) -> 0.20806877
A13: Infosys | B13: 43190 | C13: =INDEX(Infosys!$B:$K,MATCH("Sales",Infosys!$A:$A,0),MATCH($B3,Infosys!$B$16:$K$16,0)) -> 70522 | D13: =INDEX(Infosys!$B:$K,MATCH("Net profit",Infosys!$A:$A,0),MATCH($B3,Infosys!$B$16:$K$16,0)) -> 16029 | E13: =Infosys!C66 -> 79349 | F13: =INDEX(Infosys!$B:$K,MATCH("Equity Share Capital",Infosys!$A:$A,0),MATCH($B3,Infosys!$B$16:$K$16,0)) -> 1088 | G13: =INDEX(Infosys!$B:$K,MATCH("Reserves",Infosys!$A:$A,0),MATCH($B3,Infosys!$B$16:$K$16,0)) -> 63835 | H13: =F13+G13 -> 64923 | J13: =INDEX(Infosys!$B:$K,MATCH("EPS",Infosys!$A:$A,0),MATCH($B3,Infosys!$B$16:$K$16,0)) -> 36.694748 | K13: =INDEX(Infosys!$B:$K,MATCH("Return on Equity",Infosys!$A:$A,0),MATCH($B3,Infosys!$B$16:$K$16,0)) -> 0.24689247 | L13: =INDEX(Infosys!$B:$K,MATCH("Return on Capital Emp",Infosys!$A:$A,0),MATCH($B3,Infosys!$B$16:$K$16,0)) -> 0.30275195
A14: Infosys | B14: 43555 | C14: =INDEX(Infosys!$B:$K,MATCH("Sales",Infosys!$A:$A,0),MATCH($B4,Infosys!$B$16:$K$16,0)) -> 82675 | D14: =INDEX(Infosys!$B:$K,MATCH("Net profit",Infosys!$A:$A,0),MATCH($B4,Infosys!$B$16:$K$16,0)) -> 15404 | E14: =Infosys!D66 -> 84066 | F14: =INDEX(Infosys!$B:$K,MATCH("Equity Share Capital",Infosys!$A:$A,0),MATCH($B4,Infosys!$B$16:$K$16,0)) -> 2170 | G14: =INDEX(Infosys!$B:$K,MATCH("Reserves",Infosys!$A:$A,0),MATCH($B4,Infosys!$B$16:$K$16,0)) -> 62778 | H14: =F14+G14 -> 64948 | J14: =INDEX(Infosys!$B:$K,MATCH("EPS",Infosys!$A:$A,0),MATCH($B4,Infosys!$B$16:$K$16,0)) -> 35.258303 | K14: =INDEX(Infosys!$B:$K,MATCH("Return on Equity",Infosys!$A:$A,0),MATCH($B4,Infosys!$B$16:$K$16,0)) -> 0.23717435 | L14: =INDEX(Infosys!$B:$K,MATCH("Return on Capital Emp",Infosys!$A:$A,0),MATCH($B4,Infosys!$B$16:$K$16,0)) -> 0.32402923
A15: Infosys | B15: 43921 | C15: =INDEX(Infosys!$B:$K,MATCH("Sales",Infosys!$A:$A,0),MATCH($B5,Infosys!$B$16:$K$16,0)) -> 90791 | D15: =INDEX(Infosys!$B:$K,MATCH("Net profit",Infosys!$A:$A,0),MATCH($B5,Infosys!$B$16:$K$16,0)) -> 16594 | E15: =Infosys!E66 -> 91800 | F15: =INDEX(Infosys!$B:$K,MATCH("Equity Share Capital",Infosys!$A:$A,0),MATCH($B5,Infosys!$B$16:$K$16,0)) -> 2122 | G15: =INDEX(Infosys!$B:$K,MATCH("Reserves",Infosys!$A:$A,0),MATCH($B5,Infosys!$B$16:$K$16,0)) -> 63328 | H15: =F15+G15 -> 65450 | I15: =INDEX(Infosys!$B:$K,MATCH("Borrowings",Infosys!$A:$A,0),MATCH($B5,Infosys!$B$16:$K$16,0)) -> 4633 | J15: =INDEX(Infosys!$B:$K,MATCH("EPS",Infosys!$A:$A,0),MATCH($B5,Infosys!$B$16:$K$16,0)) -> 38.962198 | K15: =INDEX(Infosys!$B:$K,MATCH("Return on Equity",Infosys!$A:$A,0),MATCH($B5,Infosys!$B$16:$K$16,0)) -> 0.25353705 | L15: =INDEX(Infosys!$B:$K,MATCH("Return on Capital Emp",Infosys!$A:$A,0),MATCH($B5,Infosys!$B$16:$K$16,0)) -> 0.32847272
A16: Infosys | B16: 44286 | C16: =INDEX(Infosys!$B:$K,MATCH("Sales",Infosys!$A:$A,0),MATCH($B6,Infosys!$B$16:$K$16,0)) -> 100472 | D16: =INDEX(Infosys!$B:$K,MATCH("Net profit",Infosys!$A:$A,0),MATCH($B6,Infosys!$B$16:$K$16,0)) -> 19351 | E16: =Infosys!F66 -> 107511 | F16: =INDEX(Infosys!$B:$K,MATCH("Equity Share Capital",Infosys!$A:$A,0),MATCH($B6,Infosys!$B$16:$K$16,0)) -> 2124 | G16: =INDEX(Infosys!$B:$K,MATCH("Reserves",Infosys!$A:$A,0),MATCH($B6,Infosys!$B$16:$K$16,0)) -> 74227 | H16: =F16+G16 -> 76351 | I16: =INDEX(Infosys!$B:$K,MATCH("Borrowings",Infosys!$A:$A,0),MATCH($B6,Infosys!$B$16:$K$16,0)) -> 5325 | J16: =INDEX(Infosys!$B:$K,MATCH("EPS",Infosys!$A:$A,0),MATCH($B6,Infosys!$B$16:$K$16,0)) -> 45.41742 | K16: =INDEX(Infosys!$B:$K,MATCH("Return on Equity",Infosys!$A:$A,0),MATCH($B6,Infosys!$B$16:$K$16,0)) -> 0.25344789 | L16: =INDEX(Infosys!$B:$K,MATCH("Return on Capital Emp",Infosys!$A:$A,0),MATCH($B6,Infosys!$B$16:$K$16,0)) -> 0.35349469
A17: Infosys | B17: 44651 | C17: =INDEX(Infosys!$B:$K,MATCH("Sales",Infosys!$A:$A,0),MATCH($B7,Infosys!$B$16:$K$16,0)) -> 121641 | D17: =INDEX(Infosys!$B:$K,MATCH("Net profit",Infosys!$A:$A,0),MATCH($B7,Infosys!$B$16:$K$16,0)) -> 22110 | E17: =Infosys!G66 -> 116729 | F17: =INDEX(Infosys!$B:$K,MATCH("Equity Share Capital",Infosys!$A:$A,0),MATCH($B7,Infosys!$B$16:$K$16,0)) -> 2098 | G17: =INDEX(Infosys!$B:$K,MATCH("Reserves",Infosys!$A:$A,0),MATCH($B7,Infosys!$B$16:$K$16,0)) -> 73252 | H17: =F17+G17 -> 75350 | I17: =INDEX(Infosys!$B:$K,MATCH("Borrowings",Infosys!$A:$A,0),MATCH($B7,Infosys!$B$16:$K$16,0)) -> 5474 | J17: =INDEX(Infosys!$B:$K,MATCH("EPS",Infosys!$A:$A,0),MATCH($B7,Infosys!$B$16:$K$16,0)) -> 52.559013 | K17: =INDEX(Infosys!$B:$K,MATCH("Return on Equity",Infosys!$A:$A,0),MATCH($B7,Infosys!$B$16:$K$16,0)) -> 0.29343066 | L17: =INDEX(Infosys!$B:$K,MATCH("Return on Capital Emp",Infosys!$A:$A,0),MATCH($B7,Infosys!$B$16:$K$16,0)) -> 0.37304615
A18: Infosys | B18: 45016 | C18: =INDEX(Infosys!$B:$K,MATCH("Sales",Infosys!$A:$A,0),MATCH($B8,Infosys!$B$16:$K$16,0)) -> 146767 | D18: =INDEX(Infosys!$B:$K,MATCH("Net profit",Infosys!$A:$A,0),MATCH($B8,Infosys!$B$16:$K$16,0)) -> 24095 | E18: =Infosys!H66 -> 124596 | F18: =INDEX(Infosys!$B:$K,MATCH("Equity Share Capital",Infosys!$A:$A,0),MATCH($B8,Infosys!$B$16:$K$16,0)) -> 2069 | G18: =INDEX(Infosys!$B:$K,MATCH("Reserves",Infosys!$A:$A,0),MATCH($B8,Infosys!$B$16:$K$16,0)) -> 73338 | H18: =F18+G18 -> 75407 | I18: =INDEX(Infosys!$B:$K,MATCH("Borrowings",Infosys!$A:$A,0),MATCH($B8,Infosys!$B$16:$K$16,0)) -> 8299 | J18: =INDEX(Infosys!$B:$K,MATCH("EPS",Infosys!$A:$A,0),MATCH($B8,Infosys!$B$16:$K$16,0)) -> 58.079834 | K18: =INDEX(Infosys!$B:$K,MATCH("Return on Equity",Infosys!$A:$A,0),MATCH($B8,Infosys!$B$16:$K$16,0)) -> 0.31953267 | L18: =INDEX(Infosys!$B:$K,MATCH("Return on Capital Emp",Infosys!$A:$A,0),MATCH($B8,Infosys!$B$16:$K$16,0)) -> 0.40850909
A19: Infosys | B19: 45382 | C19: =INDEX(Infosys!$B:$K,MATCH("Sales",Infosys!$A:$A,0),MATCH($B9,Infosys!$B$16:$K$16,0)) -> 153670 | D19: =INDEX(Infosys!$B:$K,MATCH("Net profit",Infosys!$A:$A,0),MATCH($B9,Infosys!$B$16:$K$16,0)) -> 26233 | E19: =Infosys!I66 -> 136020 | F19: =INDEX(Infosys!$B:$K,MATCH("Equity Share Capital",Infosys!$A:$A,0),MATCH($B9,Infosys!$B$16:$K$16,0)) -> 2071 | G19: =INDEX(Infosys!$B:$K,MATCH("Reserves",Infosys!$A:$A,0),MATCH($B9,Infosys!$B$16:$K$16,0)) -> 86045 | H19: =F19+G19 -> 88116 | I19: =INDEX(Infosys!$B:$K,MATCH("Borrowings",Infosys!$A:$A,0),MATCH($B9,Infosys!$B$16:$K$16,0)) -> 8359 | J19: =INDEX(Infosys!$B:$K,MATCH("EPS",Infosys!$A:$A,0),MATCH($B9,Infosys!$B$16:$K$16,0)) -> 63.198343 | K19: =INDEX(Infosys!$B:$K,MATCH("Return on Equity",Infosys!$A:$A,0),MATCH($B9,Infosys!$B$16:$K$16,0)) -> 0.29770984 | L19: =INDEX(Infosys!$B:$K,MATCH("Return on Capital Emp",Infosys!$A:$A,0),MATCH($B9,Infosys!$B$16:$K$16,0)) -> 0.40468196
A20: Infosys | B20: 45747 | C20: =INDEX(Infosys!$B:$K,MATCH("Sales",Infosys!$A:$A,0),MATCH($B10,Infosys!$B$16:$K$16,0)) -> 162990 | D20: =INDEX(Infosys!$B:$K,MATCH("Net profit",Infosys!$A:$A,0),MATCH($B10,Infosys!$B$16:$K$16,0)) -> 26713 | E20: =Infosys!J66 -> 147795 | F20: =INDEX(Infosys!$B:$K,MATCH("Equity Share Capital",Infosys!$A:$A,0),MATCH($B10,Infosys!$B$16:$K$16,0)) -> 2073 | G20: =INDEX(Infosys!$B:$K,MATCH("Reserves",Infosys!$A:$A,0),MATCH($B10,Infosys!$B$16:$K$16,0)) -> 93745 | H20: =F20+G20 -> 95818 | I20: =INDEX(Infosys!$B:$K,MATCH("Borrowings",Infosys!$A:$A,0),MATCH($B10,Infosys!$B$16:$K$16,0)) -> 8227 | J20: =INDEX(Infosys!$B:$K,MATCH("EPS",Infosys!$A:$A,0),MATCH($B10,Infosys!$B$16:$K$16,0)) -> 64.317531 | K20: =INDEX(Infosys!$B:$K,MATCH("Return on Equity",Infosys!$A:$A,0),MATCH($B10,Infosys!$B$16:$K$16,0)) -> 0.27878895 | L20: =INDEX(Infosys!$B:$K,MATCH("Return on Capital Emp",Infosys!$A:$A,0),MATCH($B10,Infosys!$B$16:$K$16,0)) -> 0.37925394
A21: Infosys | B21: 46112 | C21: =INDEX(Infosys!$B:$K,MATCH("Sales",Infosys!$A:$A,0),MATCH($B11,Infosys!$B$16:$K$16,0)) -> 178650 | D21: =INDEX(Infosys!$B:$K,MATCH("Net profit",Infosys!$A:$A,0),MATCH($B11,Infosys!$B$16:$K$16,0)) -> 29440 | E21: =Infosys!K66 -> 154288 | F21: =INDEX(Infosys!$B:$K,MATCH("Equity Share Capital",Infosys!$A:$A,0),MATCH($B11,Infosys!$B$16:$K$16,0)) -> 2024 | G21: =INDEX(Infosys!$B:$K,MATCH("Reserves",Infosys!$A:$A,0),MATCH($B11,Infosys!$B$16:$K$16,0)) -> 90828 | H21: =F21+G21 -> 92852 | I21: =INDEX(Infosys!$B:$K,MATCH("Borrowings",Infosys!$A:$A,0),MATCH($B11,Infosys!$B$16:$K$16,0)) -> 9176 | J21: =INDEX(Infosys!$B:$K,MATCH("EPS",Infosys!$A:$A,0),MATCH($B11,Infosys!$B$16:$K$16,0)) -> 72.590985 | K21: =INDEX(Infosys!$B:$K,MATCH("Return on Equity",Infosys!$A:$A,0),MATCH($B11,Infosys!$B$16:$K$16,0)) -> 0.31706371 | L21: =INDEX(Infosys!$B:$K,MATCH("Return on Capital Emp",Infosys!$A:$A,0),MATCH($B11,Infosys!$B$16:$K$16,0)) -> 0.39220082
A22: HCLTech | B22: 42825 | C22: =INDEX(HCLTech!$B:$K,MATCH("Sales",HCLTech!$A:$A,0),MATCH($B2,HCLTech!$B$16:$K$16,0)) -> 47568 | D22: =INDEX(HCLTech!$B:$K,MATCH("Net profit",HCLTech!$A:$A,0),MATCH($B2,HCLTech!$B$16:$K$16,0)) -> 8606 | E22: =HCLTech!B66 -> 45762 | F22: =INDEX(HCLTech!$B:$K,MATCH("Equity Share Capital",HCLTech!$A:$A,0),MATCH($B2,HCLTech!$B$16:$K$16,0)) -> 285 | G22: =INDEX(HCLTech!$B:$K,MATCH("Reserves",HCLTech!$A:$A,0),MATCH($B2,HCLTech!$B$16:$K$16,0)) -> 32664 | H22: =F22+G22 -> 32949 | I22: =INDEX(HCLTech!$B:$K,MATCH("Borrowings",HCLTech!$A:$A,0),MATCH($B2,HCLTech!$B$16:$K$16,0)) -> 582 | J22: =INDEX(HCLTech!$B:$K,MATCH("EPS",HCLTech!$A:$A,0),MATCH($B2,HCLTech!$B$16:$K$16,0)) -> 30.158396 | K22: =INDEX(HCLTech!$B:$K,MATCH("Return on Equity",HCLTech!$A:$A,0),MATCH($B2,HCLTech!$B$16:$K$16,0)) -> 0.26119154
A23: HCLTech | B23: 43190 | C23: =INDEX(HCLTech!$B:$K,MATCH("Sales",HCLTech!$A:$A,0),MATCH($B3,HCLTech!$B$16:$K$16,0)) -> 50569 | D23: =INDEX(HCLTech!$B:$K,MATCH("Net profit",HCLTech!$A:$A,0),MATCH($B3,HCLTech!$B$16:$K$16,0)) -> 8721 | E23: =HCLTech!C66 -> 47989 | F23: =INDEX(HCLTech!$B:$K,MATCH("Equity Share Capital",HCLTech!$A:$A,0),MATCH($B3,HCLTech!$B$16:$K$16,0)) -> 278 | G23: =INDEX(HCLTech!$B:$K,MATCH("Reserves",HCLTech!$A:$A,0),MATCH($B3,HCLTech!$B$16:$K$16,0)) -> 36108 | H23: =F23+G23 -> 36386 | I23: =INDEX(HCLTech!$B:$K,MATCH("Borrowings",HCLTech!$A:$A,0),MATCH($B3,HCLTech!$B$16:$K$16,0)) -> 557 | J23: =INDEX(HCLTech!$B:$K,MATCH("EPS",HCLTech!$A:$A,0),MATCH($B3,HCLTech!$B$16:$K$16,0)) -> 31.319806 | K23: =INDEX(HCLTech!$B:$K,MATCH("Return on Equity",HCLTech!$A:$A,0),MATCH($B3,HCLTech!$B$16:$K$16,0)) -> 0.2396801 | L23: =INDEX(HCLTech!$B:$K,MATCH("Return on Capital Emp",HCLTech!$A:$A,0),MATCH($B3,HCLTech!$B$16:$K$16,0)) -> 0.31481114
A24: HCLTech | B24: 43555 | C24: =INDEX(HCLTech!$B:$K,MATCH("Sales",HCLTech!$A:$A,0),MATCH($B4,HCLTech!$B$16:$K$16,0)) -> 60427 | D24: =INDEX(HCLTech!$B:$K,MATCH("Net profit",HCLTech!$A:$A,0),MATCH($B4,HCLTech!$B$16:$K$16,0)) -> 10120 | E24: =HCLTech!D66 -> 58349 | F24: =INDEX(HCLTech!$B:$K,MATCH("Equity Share Capital",HCLTech!$A:$A,0),MATCH($B4,HCLTech!$B$16:$K$16,0)) -> 271 | G24: =INDEX(HCLTech!$B:$K,MATCH("Reserves",HCLTech!$A:$A,0),MATCH($B4,HCLTech!$B$16:$K$16,0)) -> 41095 | H24: =F24+G24 -> 41366 | I24: =INDEX(HCLTech!$B:$K,MATCH("Borrowings",HCLTech!$A:$A,0),MATCH($B4,HCLTech!$B$16:$K$16,0)) -> 4195 | J24: =INDEX(HCLTech!$B:$K,MATCH("EPS",HCLTech!$A:$A,0),MATCH($B4,HCLTech!$B$16:$K$16,0)) -> 37.30738 | K24: =INDEX(HCLTech!$B:$K,MATCH("Return on Equity",HCLTech!$A:$A,0),MATCH($B4,HCLTech!$B$16:$K$16,0)) -> 0.24464536 | L24: =INDEX(HCLTech!$B:$K,MATCH("Return on Capital Emp",HCLTech!$A:$A,0),MATCH($B4,HCLTech!$B$16:$K$16,0)) -> 0.31019102
A25: HCLTech | B25: 43921 | C25: =INDEX(HCLTech!$B:$K,MATCH("Sales",HCLTech!$A:$A,0),MATCH($B5,HCLTech!$B$16:$K$16,0)) -> 70676 | D25: =INDEX(HCLTech!$B:$K,MATCH("Net profit",HCLTech!$A:$A,0),MATCH($B5,HCLTech!$B$16:$K$16,0)) -> 11057 | E25: =HCLTech!E66 -> 82819 | F25: =INDEX(HCLTech!$B:$K,MATCH("Equity Share Capital",HCLTech!$A:$A,0),MATCH($B5,HCLTech!$B$16:$K$16,0)) -> 543 | G25: =INDEX(HCLTech!$B:$K,MATCH("Reserves",HCLTech!$A:$A,0),MATCH($B5,HCLTech!$B$16:$K$16,0)) -> 50724 | H25: =F25+G25 -> 51267 | I25: =INDEX(HCLTech!$B:$K,MATCH("Borrowings",HCLTech!$A:$A,0),MATCH($B5,HCLTech!$B$16:$K$16,0)) -> 7986 | J25: =INDEX(HCLTech!$B:$K,MATCH("EPS",HCLTech!$A:$A,0),MATCH($B5,HCLTech!$B$16:$K$16,0)) -> 40.745108 | K25: =INDEX(HCLTech!$B:$K,MATCH("Return on Equity",HCLTech!$A:$A,0),MATCH($B5,HCLTech!$B$16:$K$16,0)) -> 0.2156748 | L25: =INDEX(HCLTech!$B:$K,MATCH("Return on Capital Emp",HCLTech!$A:$A,0),MATCH($B5,HCLTech!$B$16:$K$16,0)) -> 0.27639437
A26: HCLTech | B26: 44286 | C26: =INDEX(HCLTech!$B:$K,MATCH("Sales",HCLTech!$A:$A,0),MATCH($B6,HCLTech!$B$16:$K$16,0)) -> 75379 | D26: =INDEX(HCLTech!$B:$K,MATCH("Net profit",HCLTech!$A:$A,0),MATCH($B6,HCLTech!$B$16:$K$16,0)) -> 11145 | E26: =HCLTech!F66 -> 86047 | F26: =INDEX(HCLTech!$B:$K,MATCH("Equity Share Capital",HCLTech!$A:$A,0),MATCH($B6,HCLTech!$B$16:$K$16,0)) -> 543 | G26: =INDEX(HCLTech!$B:$K,MATCH("Reserves",HCLTech!$A:$A,0),MATCH($B6,HCLTech!$B$16:$K$16,0)) -> 59370 | H26: =F26+G26 -> 59913 | I26: =INDEX(HCLTech!$B:$K,MATCH("Borrowings",HCLTech!$A:$A,0),MATCH($B6,HCLTech!$B$16:$K$16,0)) -> 6864 | J26: =INDEX(HCLTech!$B:$K,MATCH("EPS",HCLTech!$A:$A,0),MATCH($B6,HCLTech!$B$16:$K$16,0)) -> 41.069389 | K26: =INDEX(HCLTech!$B:$K,MATCH("Return on Equity",HCLTech!$A:$A,0),MATCH($B6,HCLTech!$B$16:$K$16,0)) -> 0.18601973 | L26: =INDEX(HCLTech!$B:$K,MATCH("Return on Capital Emp",HCLTech!$A:$A,0),MATCH($B6,HCLTech!$B$16:$K$16,0)) -> 0.2596842
A27: HCLTech | B27: 44651 | C27: =INDEX(HCLTech!$B:$K,MATCH("Sales",HCLTech!$A:$A,0),MATCH($B7,HCLTech!$B$16:$K$16,0)) -> 85651 | D27: =INDEX(HCLTech!$B:$K,MATCH("Net profit",HCLTech!$A:$A,0),MATCH($B7,HCLTech!$B$16:$K$16,0)) -> 13499 | E27: =HCLTech!G66 -> 88921 | F27: =INDEX(HCLTech!$B:$K,MATCH("Equity Share Capital",HCLTech!$A:$A,0),MATCH($B7,HCLTech!$B$16:$K$16,0)) -> 543 | G27: =INDEX(HCLTech!$B:$K,MATCH("Reserves",HCLTech!$A:$A,0),MATCH($B7,HCLTech!$B$16:$K$16,0)) -> 61371 | H27: =F27+G27 -> 61914 | I27: =INDEX(HCLTech!$B:$K,MATCH("Borrowings",HCLTech!$A:$A,0),MATCH($B7,HCLTech!$B$16:$K$16,0)) -> 6343 | J27: =INDEX(HCLTech!$B:$K,MATCH("EPS",HCLTech!$A:$A,0),MATCH($B7,HCLTech!$B$16:$K$16,0)) -> 49.743892 | K27: =INDEX(HCLTech!$B:$K,MATCH("Return on Equity",HCLTech!$A:$A,0),MATCH($B7,HCLTech!$B$16:$K$16,0)) -> 0.21802823 | L27: =INDEX(HCLTech!$B:$K,MATCH("Return on Capital Emp",HCLTech!$A:$A,0),MATCH($B7,HCLTech!$B$16:$K$16,0)) -> 0.25578743
A28: HCLTech | B28: 45016 | C28: =INDEX(HCLTech!$B:$K,MATCH("Sales",HCLTech!$A:$A,0),MATCH($B8,HCLTech!$B$16:$K$16,0)) -> 101456 | D28: =INDEX(HCLTech!$B:$K,MATCH("Net profit",HCLTech!$A:$A,0),MATCH($B8,HCLTech!$B$16:$K$16,0)) -> 14851 | E28: =HCLTech!H66 -> 93250 | F28: =INDEX(HCLTech!$B:$K,MATCH("Equity Share Capital",HCLTech!$A:$A,0),MATCH($B8,HCLTech!$B$16:$K$16,0)) -> 543 | G28: =INDEX(HCLTech!$B:$K,MATCH("Reserves",HCLTech!$A:$A,0),MATCH($B8,HCLTech!$B$16:$K$16,0)) -> 64862 | H28: =F28+G28 -> 65405 | I28: =INDEX(HCLTech!$B:$K,MATCH("Borrowings",HCLTech!$A:$A,0),MATCH($B8,HCLTech!$B$16:$K$16,0)) -> 4794 | J28: =INDEX(HCLTech!$B:$K,MATCH("EPS",HCLTech!$A:$A,0),MATCH($B8,HCLTech!$B$16:$K$16,0)) -> 54.72602 | K28: =INDEX(HCLTech!$B:$K,MATCH("Return on Equity",HCLTech!$A:$A,0),MATCH($B8,HCLTech!$B$16:$K$16,0)) -> 0.22706215 | L28: =INDEX(HCLTech!$B:$K,MATCH("Return on Capital Emp",HCLTech!$A:$A,0),MATCH($B8,HCLTech!$B$16:$K$16,0)) -> 0.28660369
A29: HCLTech | B29: 45382 | C29: =INDEX(HCLTech!$B:$K,MATCH("Sales",HCLTech!$A:$A,0),MATCH($B9,HCLTech!$B$16:$K$16,0)) -> 109913 | D29: =INDEX(HCLTech!$B:$K,MATCH("Net profit",HCLTech!$A:$A,0),MATCH($B9,HCLTech!$B$16:$K$16,0)) -> 15702 | E29: =HCLTech!I66 -> 99006 | F29: =INDEX(HCLTech!$B:$K,MATCH("Equity Share Capital",HCLTech!$A:$A,0),MATCH($B9,HCLTech!$B$16:$K$16,0)) -> 543 | G29: =INDEX(HCLTech!$B:$K,MATCH("Reserves",HCLTech!$A:$A,0),MATCH($B9,HCLTech!$B$16:$K$16,0)) -> 67720 | H29: =F29+G29 -> 68263 | I29: =INDEX(HCLTech!$B:$K,MATCH("Borrowings",HCLTech!$A:$A,0),MATCH($B9,HCLTech!$B$16:$K$16,0)) -> 5756 | J29: =INDEX(HCLTech!$B:$K,MATCH("EPS",HCLTech!$A:$A,0),MATCH($B9,HCLTech!$B$16:$K$16,0)) -> 57.86196 | K29: =INDEX(HCLTech!$B:$K,MATCH("Return on Equity",HCLTech!$A:$A,0),MATCH($B9,HCLTech!$B$16:$K$16,0)) -> 0.23002212 | L29: =INDEX(HCLTech!$B:$K,MATCH("Return on Capital Emp",HCLTech!$A:$A,0),MATCH($B9,HCLTech!$B$16:$K$16,0)) -> 0.29843709
A30: HCLTech | B30: 45747 | C30: =INDEX(HCLTech!$B:$K,MATCH("Sales",HCLTech!$A:$A,0),MATCH($B10,HCLTech!$B$16:$K$16,0)) -> 117055 | D30: =INDEX(HCLTech!$B:$K,MATCH("Net profit",HCLTech!$A:$A,0),MATCH($B10,HCLTech!$B$16:$K$16,0)) -> 17390 | E30: =HCLTech!J66 -> 104480 | F30: =INDEX(HCLTech!$B:$K,MATCH("Equity Share Capital",HCLTech!$A:$A,0),MATCH($B10,HCLTech!$B$16:$K$16,0)) -> 543 | G30: =INDEX(HCLTech!$B:$K,MATCH("Reserves",HCLTech!$A:$A,0),MATCH($B10,HCLTech!$B$16:$K$16,0)) -> 69112 | H30: =F30+G30 -> 69655 | I30: =INDEX(HCLTech!$B:$K,MATCH("Borrowings",HCLTech!$A:$A,0),MATCH($B10,HCLTech!$B$16:$K$16,0)) -> 6276 | J30: =INDEX(HCLTech!$B:$K,MATCH("EPS",HCLTech!$A:$A,0),MATCH($B10,HCLTech!$B$16:$K$16,0)) -> 64.082249 | K30: =INDEX(HCLTech!$B:$K,MATCH("Return on Equity",HCLTech!$A:$A,0),MATCH($B10,HCLTech!$B$16:$K$16,0)) -> 0.24965903 | L30: =INDEX(HCLTech!$B:$K,MATCH("Return on Capital Emp",HCLTech!$A:$A,0),MATCH($B10,HCLTech!$B$16:$K$16,0)) -> 0.31883961
A31: HCLTech | B31: 46112 | C31: =INDEX(HCLTech!$B:$K,MATCH("Sales",HCLTech!$A:$A,0),MATCH($B11,HCLTech!$B$16:$K$16,0)) -> 130144 | D31: =INDEX(HCLTech!$B:$K,MATCH("Net profit",HCLTech!$A:$A,0),MATCH($B11,HCLTech!$B$16:$K$16,0)) -> 16642 | E31: =HCLTech!K66 -> 116258 | F31: =INDEX(HCLTech!$B:$K,MATCH("Equity Share Capital",HCLTech!$A:$A,0),MATCH($B11,HCLTech!$B$16:$K$16,0)) -> 543 | G31: =INDEX(HCLTech!$B:$K,MATCH("Reserves",HCLTech!$A:$A,0),MATCH($B11,HCLTech!$B$16:$K$16,0)) -> 74622 | H31: =F31+G31 -> 75165 | I31: =INDEX(HCLTech!$B:$K,MATCH("Borrowings",HCLTech!$A:$A,0),MATCH($B11,HCLTech!$B$16:$K$16,0)) -> 5215 | J31: =INDEX(HCLTech!$B:$K,MATCH("EPS",HCLTech!$A:$A,0),MATCH($B11,HCLTech!$B$16:$K$16,0)) -> 61.325865 | K31: =INDEX(HCLTech!$B:$K,MATCH("Return on Equity",HCLTech!$A:$A,0),MATCH($B11,HCLTech!$B$16:$K$16,0)) -> 0.22140624 | L31: =INDEX(HCLTech!$B:$K,MATCH("Return on Capital Emp",HCLTech!$A:$A,0),MATCH($B11,HCLTech!$B$16:$K$16,0)) -> 0.29391406
A32: Wipro | B32: 42825 | C32: =INDEX(Wipro!$B:$K,MATCH("Sales",Wipro!$A:$A,0),MATCH($B2,Wipro!$B$16:$K$16,0)) -> 55448.4 | D32: =INDEX(Wipro!$B:$K,MATCH("Net profit",Wipro!$A:$A,0),MATCH($B2,Wipro!$B$16:$K$16,0)) -> 8493.1 | E32: =Wipro!B66 -> 78672.2 | F32: =INDEX(Wipro!$B:$K,MATCH("Equity Share Capital",Wipro!$A:$A,0),MATCH($B2,Wipro!$B$16:$K$16,0)) -> 486.1 | G32: =INDEX(Wipro!$B:$K,MATCH("Reserves",Wipro!$A:$A,0),MATCH($B2,Wipro!$B$16:$K$16,0)) -> 51184.1 | H32: =F32+G32 -> 51670.2 | I32: =INDEX(Wipro!$B:$K,MATCH("Borrowings",Wipro!$A:$A,0),MATCH($B2,Wipro!$B$16:$K$16,0)) -> 14241.2 | J32: =INDEX(Wipro!$B:$K,MATCH("EPS",Wipro!$A:$A,0),MATCH($B2,Wipro!$B$16:$K$16,0)) -> 6.5508916 | K32: =INDEX(Wipro!$B:$K,MATCH("Return on Equity",Wipro!$A:$A,0),MATCH($B2,Wipro!$B$16:$K$16,0)) -> 0.16437134
A33: Wipro | B33: 43190 | C33: =INDEX(Wipro!$B:$K,MATCH("Sales",Wipro!$A:$A,0),MATCH($B3,Wipro!$B$16:$K$16,0)) -> 54487.1 | D33: =INDEX(Wipro!$B:$K,MATCH("Net profit",Wipro!$A:$A,0),MATCH($B3,Wipro!$B$16:$K$16,0)) -> 8002.8 | E33: =Wipro!C66 -> 75390.8 | F33: =INDEX(Wipro!$B:$K,MATCH("Equity Share Capital",Wipro!$A:$A,0),MATCH($B3,Wipro!$B$16:$K$16,0)) -> 904.8 | G33: =INDEX(Wipro!$B:$K,MATCH("Reserves",Wipro!$A:$A,0),MATCH($B3,Wipro!$B$16:$K$16,0)) -> 47021.5 | H33: =F33+G33 -> 47926.3 | I33: =INDEX(Wipro!$B:$K,MATCH("Borrowings",Wipro!$A:$A,0),MATCH($B3,Wipro!$B$16:$K$16,0)) -> 13901.2 | J33: =INDEX(Wipro!$B:$K,MATCH("EPS",Wipro!$A:$A,0),MATCH($B3,Wipro!$B$16:$K$16,0)) -> 6.6338956 | K33: =INDEX(Wipro!$B:$K,MATCH("Return on Equity",Wipro!$A:$A,0),MATCH($B3,Wipro!$B$16:$K$16,0)) -> 0.16698139 | L33: =INDEX(Wipro!$B:$K,MATCH("Return on Capital Emp",Wipro!$A:$A,0),MATCH($B3,Wipro!$B$16:$K$16,0)) -> 0.16948948
A34: Wipro | B34: 43555 | C34: =INDEX(Wipro!$B:$K,MATCH("Sales",Wipro!$A:$A,0),MATCH($B4,Wipro!$B$16:$K$16,0)) -> 59018.9 | D34: =INDEX(Wipro!$B:$K,MATCH("Net profit",Wipro!$A:$A,0),MATCH($B4,Wipro!$B$16:$K$16,0)) -> 9003.7 | E34: =Wipro!D66 -> 82586.4 | F34: =INDEX(Wipro!$B:$K,MATCH("Equity Share Capital",Wipro!$A:$A,0),MATCH($B4,Wipro!$B$16:$K$16,0)) -> 1206.8 | G34: =INDEX(Wipro!$B:$K,MATCH("Reserves",Wipro!$A:$A,0),MATCH($B4,Wipro!$B$16:$K$16,0)) -> 55215.8 | H34: =F34+G34 -> 56422.6 | I34: =INDEX(Wipro!$B:$K,MATCH("Borrowings",Wipro!$A:$A,0),MATCH($B4,Wipro!$B$16:$K$16,0)) -> 9946.7 | J34: =INDEX(Wipro!$B:$K,MATCH("EPS",Wipro!$A:$A,0),MATCH($B4,Wipro!$B$16:$K$16,0)) -> 7.4608673 | K34: =INDEX(Wipro!$B:$K,MATCH("Return on Equity",Wipro!$A:$A,0),MATCH($B4,Wipro!$B$16:$K$16,0)) -> 0.15957613 | L34: =INDEX(Wipro!$B:$K,MATCH("Return on Capital Emp",Wipro!$A:$A,0),MATCH($B4,Wipro!$B$16:$K$16,0)) -> 0.19157576
A35: Wipro | B35: 43921 | C35: =INDEX(Wipro!$B:$K,MATCH("Sales",Wipro!$A:$A,0),MATCH($B5,Wipro!$B$16:$K$16,0)) -> 61137.6 | D35: =INDEX(Wipro!$B:$K,MATCH("Net profit",Wipro!$A:$A,0),MATCH($B5,Wipro!$B$16:$K$16,0)) -> 9722.3 | E35: =Wipro!E66 -> 80999.6 | F35: =INDEX(Wipro!$B:$K,MATCH("Equity Share Capital",Wipro!$A:$A,0),MATCH($B5,Wipro!$B$16:$K$16,0)) -> 1142.7 | G35: =INDEX(Wipro!$B:$K,MATCH("Reserves",Wipro!$A:$A,0),MATCH($B5,Wipro!$B$16:$K$16,0)) -> 54179 | H35: =F35+G35 -> 55321.7 | I35: =INDEX(Wipro!$B:$K,MATCH("Borrowings",Wipro!$A:$A,0),MATCH($B5,Wipro!$B$16:$K$16,0)) -> 9724 | J35: =INDEX(Wipro!$B:$K,MATCH("EPS",Wipro!$A:$A,0),MATCH($B5,Wipro!$B$16:$K$16,0)) -> 8.5084058 | K35: =INDEX(Wipro!$B:$K,MATCH("Return on Equity",Wipro!$A:$A,0),MATCH($B5,Wipro!$B$16:$K$16,0)) -> 0.17574116 | L35: =INDEX(Wipro!$B:$K,MATCH("Return on Capital Emp",Wipro!$A:$A,0),MATCH($B5,Wipro!$B$16:$K$16,0)) -> 0.19761367
A36: Wipro | B36: 44286 | C36: =INDEX(Wipro!$B:$K,MATCH("Sales",Wipro!$A:$A,0),MATCH($B6,Wipro!$B$16:$K$16,0)) -> 61934.9 | D36: =INDEX(Wipro!$B:$K,MATCH("Net profit",Wipro!$A:$A,0),MATCH($B6,Wipro!$B$16:$K$16,0)) -> 10796.4 | E36: =Wipro!F66 -> 82565.8 | F36: =INDEX(Wipro!$B:$K,MATCH("Equity Share Capital",Wipro!$A:$A,0),MATCH($B6,Wipro!$B$16:$K$16,0)) -> 1095.8 | G36: =INDEX(Wipro!$B:$K,MATCH("Reserves",Wipro!$A:$A,0),MATCH($B6,Wipro!$B$16:$K$16,0)) -> 53805.2 | H36: =F36+G36 -> 54901 | I36: =INDEX(Wipro!$B:$K,MATCH("Borrowings",Wipro!$A:$A,0),MATCH($B6,Wipro!$B$16:$K$16,0)) -> 10451.4 | J36: =INDEX(Wipro!$B:$K,MATCH("EPS",Wipro!$A:$A,0),MATCH($B6,Wipro!$B$16:$K$16,0)) -> 9.8522581 | K36: =INDEX(Wipro!$B:$K,MATCH("Return on Equity",Wipro!$A:$A,0),MATCH($B6,Wipro!$B$16:$K$16,0)) -> 0.19665216 | L36: =INDEX(Wipro!$B:$K,MATCH("Return on Capital Emp",Wipro!$A:$A,0),MATCH($B6,Wipro!$B$16:$K$16,0)) -> 0.22104156
A37: Wipro | B37: 44651 | C37: =INDEX(Wipro!$B:$K,MATCH("Sales",Wipro!$A:$A,0),MATCH($B7,Wipro!$B$16:$K$16,0)) -> 79312 | D37: =INDEX(Wipro!$B:$K,MATCH("Net profit",Wipro!$A:$A,0),MATCH($B7,Wipro!$B$16:$K$16,0)) -> 12229.6 | E37: =Wipro!G66 -> 107275.6 | F37: =INDEX(Wipro!$B:$K,MATCH("Equity Share Capital",Wipro!$A:$A,0),MATCH($B7,Wipro!$B$16:$K$16,0)) -> 1096.4 | G37: =INDEX(Wipro!$B:$K,MATCH("Reserves",Wipro!$A:$A,0),MATCH($B7,Wipro!$B$16:$K$16,0)) -> 64306.6 | H37: =F37+G37 -> 65403 | I37: =INDEX(Wipro!$B:$K,MATCH("Borrowings",Wipro!$A:$A,0),MATCH($B7,Wipro!$B$16:$K$16,0)) -> 17592.9 | J37: =INDEX(Wipro!$B:$K,MATCH("EPS",Wipro!$A:$A,0),MATCH($B7,Wipro!$B$16:$K$16,0)) -> 11.154222 | K37: =INDEX(Wipro!$B:$K,MATCH("Return on Equity",Wipro!$A:$A,0),MATCH($B7,Wipro!$B$16:$K$16,0)) -> 0.18698836 | L37: =INDEX(Wipro!$B:$K,MATCH("Return on Capital Emp",Wipro!$A:$A,0),MATCH($B7,Wipro!$B$16:$K$16,0)) -> 0.21130407
A38: Wipro | B38: 45016 | C38: =INDEX(Wipro!$B:$K,MATCH("Sales",Wipro!$A:$A,0),MATCH($B8,Wipro!$B$16:$K$16,0)) -> 90487.6 | D38: =INDEX(Wipro!$B:$K,MATCH("Net profit",Wipro!$A:$A,0),MATCH($B8,Wipro!$B$16:$K$16,0)) -> 11350 | E38: =Wipro!H66 -> 116923.7 | F38: =INDEX(Wipro!$B:$K,MATCH("Equity Share Capital",Wipro!$A:$A,0),MATCH($B8,Wipro!$B$16:$K$16,0)) -> 1097.6 | G38: =INDEX(Wipro!$B:$K,MATCH("Reserves",Wipro!$A:$A,0),MATCH($B8,Wipro!$B$16:$K$16,0)) -> 76570.3 | H38: =F38+G38 -> 77667.9 | I38: =INDEX(Wipro!$B:$K,MATCH("Borrowings",Wipro!$A:$A,0),MATCH($B8,Wipro!$B$16:$K$16,0)) -> 17466.6 | J38: =INDEX(Wipro!$B:$K,MATCH("EPS",Wipro!$A:$A,0),MATCH($B8,Wipro!$B$16:$K$16,0)) -> 10.340932 | K38: =INDEX(Wipro!$B:$K,MATCH("Return on Equity",Wipro!$A:$A,0),MATCH($B8,Wipro!$B$16:$K$16,0)) -> 0.14613502 | L38: =INDEX(Wipro!$B:$K,MATCH("Return on Capital Emp",Wipro!$A:$A,0),MATCH($B8,Wipro!$B$16:$K$16,0)) -> 0.17709947
A39: Wipro | B39: 45382 | C39: =INDEX(Wipro!$B:$K,MATCH("Sales",Wipro!$A:$A,0),MATCH($B9,Wipro!$B$16:$K$16,0)) -> 89760.3 | D39: =INDEX(Wipro!$B:$K,MATCH("Net profit",Wipro!$A:$A,0),MATCH($B9,Wipro!$B$16:$K$16,0)) -> 11045.2 | E39: =Wipro!I66 -> 114608.9 | F39: =INDEX(Wipro!$B:$K,MATCH("Equity Share Capital",Wipro!$A:$A,0),MATCH($B9,Wipro!$B$16:$K$16,0)) -> 1045 | G39: =INDEX(Wipro!$B:$K,MATCH("Reserves",Wipro!$A:$A,0),MATCH($B9,Wipro!$B$16:$K$16,0)) -> 73488 | H39: =F39+G39 -> 74533 | I39: =INDEX(Wipro!$B:$K,MATCH("Borrowings",Wipro!$A:$A,0),MATCH($B9,Wipro!$B$16:$K$16,0)) -> 16464.9 | J39: =INDEX(Wipro!$B:$K,MATCH("EPS",Wipro!$A:$A,0),MATCH($B9,Wipro!$B$16:$K$16,0)) -> 10.569266 | K39: =INDEX(Wipro!$B:$K,MATCH("Return on Equity",Wipro!$A:$A,0),MATCH($B9,Wipro!$B$16:$K$16,0)) -> 0.14819208 | L39: =INDEX(Wipro!$B:$K,MATCH("Return on Capital Emp",Wipro!$A:$A,0),MATCH($B9,Wipro!$B$16:$K$16,0)) -> 0.1716649
A40: Wipro | B40: 45747 | C40: =INDEX(Wipro!$B:$K,MATCH("Sales",Wipro!$A:$A,0),MATCH($B10,Wipro!$B$16:$K$16,0)) -> 89088.4 | D40: =INDEX(Wipro!$B:$K,MATCH("Net profit",Wipro!$A:$A,0),MATCH($B10,Wipro!$B$16:$K$16,0)) -> 13135.4 | E40: =Wipro!J66 -> 127929.1 | F40: =INDEX(Wipro!$B:$K,MATCH("Equity Share Capital",Wipro!$A:$A,0),MATCH($B10,Wipro!$B$16:$K$16,0)) -> 2094.4 | G40: =INDEX(Wipro!$B:$K,MATCH("Reserves",Wipro!$A:$A,0),MATCH($B10,Wipro!$B$16:$K$16,0)) -> 80269.7 | H40: =F40+G40 -> 82364.1 | I40: =INDEX(Wipro!$B:$K,MATCH("Borrowings",Wipro!$A:$A,0),MATCH($B10,Wipro!$B$16:$K$16,0)) -> 19203.5 | J40: =INDEX(Wipro!$B:$K,MATCH("EPS",Wipro!$A:$A,0),MATCH($B10,Wipro!$B$16:$K$16,0)) -> 12.543234 | K40: =INDEX(Wipro!$B:$K,MATCH("Return on Equity",Wipro!$A:$A,0),MATCH($B10,Wipro!$B$16:$K$16,0)) -> 0.15947968 | L40: =INDEX(Wipro!$B:$K,MATCH("Return on Capital Emp",Wipro!$A:$A,0),MATCH($B10,Wipro!$B$16:$K$16,0)) -> 0.19705191
...

Sheet Final_Data
A1: Company | B1: Year | C1: Revenue | D1: Net Profit | E1: Total Assets | F1: Equity Capital | G1: Reserves | H1: Shareholders' Equity | I1: Borrowings | J1: EPS | K1: ROE | L1: ROCE | M1: Net Profit Margin | N1: ROA | O1: Debt-to-Equity Ratio
A2: TCS | B2: 42825 | C2: 117966 | D2: 26289 | E2: 102333 | F2: 197 | G2: 86017 | H2: 86214 | I2: 289 | J2: 66.708112 | K2: 0.30492727 | M2: =IF(OR(C2="",D2=""),"",D2/C2) -> 0.22285235 | N2: =IF(OR(D2="",E2=""),"",D2/E2) -> 0.2568966 | O2: =IF(OR(I2="",H2=""),"",I2/H2) -> 0.0033521238
A3: TCS | B3: 43190 | C3: 123104 | D3: 25826 | E3: 105126 | F3: 191 | G3: 84937 | H3: 85128 | I3: 247 | J3: 67.455467 | K3: 0.30337844 | L3: 0.39730507 | M3: =IF(OR(C3="",D3=""),"",D3/C3) -> 0.2097901 | N3: =IF(OR(D3="",E3=""),"",D3/E3) -> 0.2456671 | O3: =IF(OR(I3="",H3=""),"",I3/H3) -> 0.002901513
A4: TCS | B4: 43555 | C4: 146463 | D4: 31472 | E4: 113901 | F4: 375 | G4: 89071 | H4: 89446 | I4: 62 | J4: 83.871655 | K4: 0.35185475 | L4: 0.47758787 | M4: =IF(OR(C4="",D4=""),"",D4/C4) -> 0.21488021 | N4: =IF(OR(D4="",E4=""),"",D4/E4) -> 0.27631013 | O4: =IF(OR(I4="",H4=""),"",I4/H4) -> 0.00069315565
A5: TCS | B5: 43921 | C5: 156949 | D5: 32340 | E5: 120127 | F5: 375 | G5: 83751 | H5: 84126 | I5: 8174 | J5: 86.184842 | K5: 0.38442336 | L5: 0.4749186 | M5: =IF(OR(C5="",D5=""),"",D5/C5) -> 0.2060542 | N5: =IF(OR(D5="",E5=""),"",D5/E5) -> 0.26921508 | O5: =IF(OR(I5="",H5=""),"",I5/H5) -> 0.097163778
A6: TCS | B6: 44286 | C6: 164177 | D6: 32430 | E6: 129992 | F6: 370 | G6: 86063 | H6: 86433 | I6: 7795 | J6: 87.669974 | K6: 0.37520392 | L6: 0.47603577 | M6: =IF(OR(C6="",D6=""),"",D6/C6) -> 0.19753071 | N6: =IF(OR(D6="",E6=""),"",D6/E6) -> 0.24947689 | O6: =IF(OR(I6="",H6=""),"",I6/H6) -> 0.090185462
A7: TCS | B7: 44651 | C7: 191754 | D7: 38327 | E7: 140924 | F7: 366 | G7: 88773 | H7: 89139 | I7: 7818 | J7: 104.74434 | K7: 0.42996892 | L7: 0.5489029 | M7: =IF(OR(C7="",D7=""),"",D7/C7) -> 0.19987588 | N7: =IF(OR(D7="",E7=""),"",D7/E7) -> 0.27196929 | O7: =IF(OR(I7="",H7=""),"",I7/H7) -> 0.087705718
A8: TCS | B8: 45016 | C8: 225458 | D8: 42147 | E8: 142859 | F8: 366 | G8: 90058 | H8: 90424 | I8: 7688 | J8: 115.18406 | K8: 0.46610413 | L8: 0.591442 | M8: =IF(OR(C8="",D8=""),"",D8/C8) -> 0.18693947 | N8: =IF(OR(D8="",E8=""),"",D8/E8) -> 0.29502516 | O8: =IF(OR(I8="",H8=""),"",I8/H8) -> 0.085021676
A9: TCS | B9: 45382 | C9: 240893 | D9: 45908 | E9: 145472 | F9: 362 | G9: 90127 | H9: 90489 | I9: 8021 | J9: 126.88428 | K9: 0.50733238 | L9: 0.63853485 | M9: =IF(OR(C9="",D9=""),"",D9/C9) -> 0.19057424 | N9: =IF(OR(D9="",E9=""),"",D9/E9) -> 0.31557963 | O9: =IF(OR(I9="",H9=""),"",I9/H9) -> 0.088640608
A10: TCS | B10: 45747 | C10: 255324 | D10: 48553 | E10: 158649 | F10: 362 | G10: 94394 | H10: 94756 | I10: 9392 | J10: 134.19474 | K10: 0.51240027 | L10: 0.65259699 | M10: =IF(OR(C10="",D10=""),"",D10/C10) -> 0.1901623 | N10: =IF(OR(D10="",E10=""),"",D10/E10) -> 0.30604038 | O10: =IF(OR(I10="",H10=""),"",I10/H10) -> 0.099117734
A11: TCS | B11: 46112 | C11: 267021 | D11: 49210 | E11: 181167 | F11: 362 | G11: 106878 | H11: 107240 | I11: 11283 | J11: 136.01061 | K11: 0.45887728 | L11: 0.59921588 | M11: =IF(OR(C11="",D11=""),"",D11/C11) -> 0.18429262 | N11: =IF(OR(D11="",E11=""),"",D11/E11) -> 0.27162784 | O11: =IF(OR(I11="",H11=""),"",I11/H11) -> 0.10521261
A12: Infosys | B12: 42825 | C12: 68484 | D12: 14353 | E12: 83148 | F12: 1144 | G12: 67838 | H12: 68982 | J12: 31.243606 | K12: 0.20806877 | M12: =IF(OR(C12="",D12=""),"",D12/C12) -> 0.2095818 | N12: =IF(OR(D12="",E12=""),"",D12/E12) -> 0.17261991 | O12: =IF(OR(I12="",H12=""),"",I12/H12)
A13: Infosys | B13: 43190 | C13: 70522 | D13: 16029 | E13: 79349 | F13: 1088 | G13: 63835 | H13: 64923 | J13: 36.694748 | K13: 0.24689247 | L13: 0.30275195 | M13: =IF(OR(C13="",D13=""),"",D13/C13) -> 0.22729077 | N13: =IF(OR(D13="",E13=""),"",D13/E13) -> 0.20200633 | O13: =IF(OR(I13="",H13=""),"",I13/H13)
A14: Infosys | B14: 43555 | C14: 82675 | D14: 15404 | E14: 84066 | F14: 2170 | G14: 62778 | H14: 64948 | J14: 35.258303 | K14: 0.23717435 | L14: 0.32402923 | M14: =IF(OR(C14="",D14=""),"",D14/C14) -> 0.18631993 | N14: =IF(OR(D14="",E14=""),"",D14/E14) -> 0.18323698 | O14: =IF(OR(I14="",H14=""),"",I14/H14)
A15: Infosys | B15: 43921 | C15: 90791 | D15: 16594 | E15: 91800 | F15: 2122 | G15: 63328 | H15: 65450 | I15: 4633 | J15: 38.962198 | K15: 0.25353705 | L15: 0.32847272 | M15: =IF(OR(C15="",D15=""),"",D15/C15) -> 0.18277142 | N15: =IF(OR(D15="",E15=""),"",D15/E15) -> 0.18076253 | O15: =IF(OR(I15="",H15=""),"",I15/H15) -> 0.07078686
A16: Infosys | B16: 44286 | C16: 100472 | D16: 19351 | E16: 107511 | F16: 2124 | G16: 74227 | H16: 76351 | I16: 5325 | J16: 45.41742 | K16: 0.25344789 | L16: 0.35349469 | M16: =IF(OR(C16="",D16=""),"",D16/C16) -> 0.19260092 | N16: =IF(OR(D16="",E16=""),"",D16/E16) -> 0.17999088 | O16: =IF(OR(I16="",H16=""),"",I16/H16) -> 0.069743684
A17: Infosys | B17: 44651 | C17: 121641 | D17: 22110 | E17: 116729 | F17: 2098 | G17: 73252 | H17: 75350 | I17: 5474 | J17: 52.559013 | K17: 0.29343066 | L17: 0.37304615 | M17: =IF(OR(C17="",D17=""),"",D17/C17) -> 0.18176437 | N17: =IF(OR(D17="",E17=""),"",D17/E17) -> 0.18941309 | O17: =IF(OR(I17="",H17=""),"",I17/H17) -> 0.072647644
A18: Infosys | B18: 45016 | C18: 146767 | D18: 24095 | E18: 124596 | F18: 2069 | G18: 73338 | H18: 75407 | I18: 8299 | J18: 58.079834 | K18: 0.31953267 | L18: 0.40850909 | M18: =IF(OR(C18="",D18=""),"",D18/C18) -> 0.16417178 | N18: =IF(OR(D18="",E18=""),"",D18/E18) -> 0.19338502 | O18: =IF(OR(I18="",H18=""),"",I18/H18) -> 0.1100561
A19: Infosys | B19: 45382 | C19: 153670 | D19: 26233 | E19: 136020 | F19: 2071 | G19: 86045 | H19: 88116 | I19: 8359 | J19: 63.198343 | K19: 0.29770984 | L19: 0.40468196 | M19: =IF(OR(C19="",D19=""),"",D19/C19) -> 0.17070996 | N19: =IF(OR(D19="",E19=""),"",D19/E19) -> 0.19286134 | O19: =IF(OR(I19="",H19=""),"",I19/H19) -> 0.094863589
A20: Infosys | B20: 45747 | C20: 162990 | D20: 26713 | E20: 147795 | F20: 2073 | G20: 93745 | H20: 95818 | I20: 8227 | J20: 64.317531 | K20: 0.27878895 | L20: 0.37925394 | M20: =IF(OR(C20="",D20=""),"",D20/C20) -> 0.16389349 | N20: =IF(OR(D20="",E20=""),"",D20/E20) -> 0.1807436 | O20: =IF(OR(I20="",H20=""),"",I20/H20) -> 0.085860694
A21: Infosys | B21: 46112 | C21: 178650 | D21: 29440 | E21: 154288 | F21: 2024 | G21: 90828 | H21: 92852 | I21: 9176 | J21: 72.590985 | K21: 0.31706371 | L21: 0.39220082 | M21: =IF(OR(C21="",D21=""),"",D21/C21) -> 0.16479149 | N21: =IF(OR(D21="",E21=""),"",D21/E21) -> 0.19081199 | O21: =IF(OR(I21="",H21=""),"",I21/H21) -> 0.098823935
A22: HCLTech | B22: 42825 | C22: 47568 | D22: 8606 | E22: 45762 | F22: 285 | G22: 32664 | H22: 32949 | I22: 582 | J22: 30.158396 | K22: 0.26119154 | M22: =IF(OR(C22="",D22=""),"",D22/C22) -> 0.18091995 | N22: =IF(OR(D22="",E22=""),"",D22/E22) -> 0.18805996 | O22: =IF(OR(I22="",H22=""),"",I22/H22) -> 0.017663662
A23: HCLTech | B23: 43190 | C23: 50569 | D23: 8721 | E23: 47989 | F23: 278 | G23: 36108 | H23: 36386 | I23: 557 | J23: 31.319806 | K23: 0.2396801 | L23: 0.31481114 | M23: =IF(OR(C23="",D23=""),"",D23/C23) -> 0.17245743 | N23: =IF(OR(D23="",E23=""),"",D23/E23) -> 0.18172915 | O23: =IF(OR(I23="",H23=""),"",I23/H23) -> 0.015308086
A24: HCLTech | B24: 43555 | C24: 60427 | D24: 10120 | E24: 58349 | F24: 271 | G24: 41095 | H24: 41366 | I24: 4195 | J24: 37.30738 | K24: 0.24464536 | L24: 0.31019102 | M24: =IF(OR(C24="",D24=""),"",D24/C24) -> 0.1674748 | N24: =IF(OR(D24="",E24=""),"",D24/E24) -> 0.17343913 | O24: =IF(OR(I24="",H24=""),"",I24/H24) -> 0.10141179
A25: HCLTech | B25: 43921 | C25: 70676 | D25: 11057 | E25: 82819 | F25: 543 | G25: 50724 | H25: 51267 | I25: 7986 | J25: 40.745108 | K25: 0.2156748 | L25: 0.27639437 | M25: =IF(OR(C25="",D25=""),"",D25/C25) -> 0.15644632 | N25: =IF(OR(D25="",E25=""),"",D25/E25) -> 0.13350801 | O25: =IF(OR(I25="",H25=""),"",I25/H25) -> 0.15577272
A26: HCLTech | B26: 44286 | C26: 75379 | D26: 11145 | E26: 86047 | F26: 543 | G26: 59370 | H26: 59913 | I26: 6864 | J26: 41.069389 | K26: 0.18601973 | L26: 0.2596842 | M26: =IF(OR(C26="",D26=""),"",D26/C26) -> 0.14785285 | N26: =IF(OR(D26="",E26=""),"",D26/E26) -> 0.12952224 | O26: =IF(OR(I26="",H26=""),"",I26/H26) -> 0.11456612
A27: HCLTech | B27: 44651 | C27: 85651 | D27: 13499 | E27: 88921 | F27: 543 | G27: 61371 | H27: 61914 | I27: 6343 | J27: 49.743892 | K27: 0.21802823 | L27: 0.25578743 | M27: =IF(OR(C27="",D27=""),"",D27/C27) -> 0.1576047 | N27: =IF(OR(D27="",E27=""),"",D27/E27) -> 0.15180891 | O27: =IF(OR(I27="",H27=""),"",I27/H27) -> 0.10244856
A28: HCLTech | B28: 45016 | C28: 101456 | D28: 14851 | E28: 93250 | F28: 543 | G28: 64862 | H28: 65405 | I28: 4794 | J28: 54.72602 | K28: 0.22706215 | L28: 0.28660369 | M28: =IF(OR(C28="",D28=""),"",D28/C28) -> 0.14637873 | N28: =IF(OR(D28="",E28=""),"",D28/E28) -> 0.15926005 | O28: =IF(OR(I28="",H28=""),"",I28/H28) -> 0.073297149
A29: HCLTech | B29: 45382 | C29: 109913 | D29: 15702 | E29: 99006 | F29: 543 | G29: 67720 | H29: 68263 | I29: 5756 | J29: 57.86196 | K29: 0.23002212 | L29: 0.29843709 | M29: =IF(OR(C29="",D29=""),"",D29/C29) -> 0.14285844 | N29: =IF(OR(D29="",E29=""),"",D29/E29) -> 0.15859645 | O29: =IF(OR(I29="",H29=""),"",I29/H29) -> 0.084320935
A30: HCLTech | B30: 45747 | C30: 117055 | D30: 17390 | E30: 104480 | F30: 543 | G30: 69112 | H30: 69655 | I30: 6276 | J30: 64.082249 | K30: 0.24965903 | L30: 0.31883961 | M30: =IF(OR(C30="",D30=""),"",D30/C30) -> 0.14856264 | N30: =IF(OR(D30="",E30=""),"",D30/E30) -> 0.16644334 | O30: =IF(OR(I30="",H30=""),"",I30/H30) -> 0.090101213
A31: HCLTech | B31: 46112 | C31: 130144 | D31: 16642 | E31: 116258 | F31: 543 | G31: 74622 | H31: 75165 | I31: 5215 | J31: 61.325865 | K31: 0.22140624 | L31: 0.29391406 | M31: =IF(OR(C31="",D31=""),"",D31/C31) -> 0.12787374 | N31: =IF(OR(D31="",E31=""),"",D31/E31) -> 0.14314714 | O31: =IF(OR(I31="",H31=""),"",I31/H31) -> 0.069380696
A32: Wipro | B32: 42825 | C32: 55448.4 | D32: 8493.1 | E32: 78672.2 | F32: 486.1 | G32: 51184.1 | H32: 51670.2 | I32: 14241.2 | J32: 6.5508916 | K32: 0.16437134 | M32: =IF(OR(C32="",D32=""),"",D32/C32) -> 0.15317124 | N32: =IF(OR(D32="",E32=""),"",D32/E32) -> 0.10795554 | O32: =IF(OR(I32="",H32=""),"",I32/H32) -> 0.27561728
A33: Wipro | B33: 43190 | C33: 54487.1 | D33: 8002.8 | E33: 75390.8 | F33: 904.8 | G33: 47021.5 | H33: 47926.3 | I33: 13901.2 | J33: 6.6338956 | K33: 0.16698139 | L33: 0.16948948 | M33: =IF(OR(C33="",D33=""),"",D33/C33) -> 0.14687513 | N33: =IF(OR(D33="",E33=""),"",D33/E33) -> 0.10615088 | O33: =IF(OR(I33="",H33=""),"",I33/H33) -> 0.29005369
A34: Wipro | B34: 43555 | C34: 59018.9 | D34: 9003.7 | E34: 82586.4 | F34: 1206.8 | G34: 55215.8 | H34: 56422.6 | I34: 9946.7 | J34: 7.4608673 | K34: 0.15957613 | L34: 0.19157576 | M34: =IF(OR(C34="",D34=""),"",D34/C34) -> 0.15255622 | N34: =IF(OR(D34="",E34=""),"",D34/E34) -> 0.10902158 | O34: =IF(OR(I34="",H34=""),"",I34/H34) -> 0.17628929
A35: Wipro | B35: 43921 | C35: 61137.6 | D35: 9722.3 | E35: 80999.6 | F35: 1142.7 | G35: 54179 | H35: 55321.7 | I35: 9724 | J35: 8.5084058 | K35: 0.17574116 | L35: 0.19761367 | M35: =IF(OR(C35="",D35=""),"",D35/C35) -> 0.15902325 | N35: =IF(OR(D35="",E35=""),"",D35/E35) -> 0.12002899 | O35: =IF(OR(I35="",H35=""),"",I35/H35) -> 0.17577189
A36: Wipro | B36: 44286 | C36: 61934.9 | D36: 10796.4 | E36: 82565.8 | F36: 1095.8 | G36: 53805.2 | H36: 54901 | I36: 10451.4 | J36: 9.8522581 | K36: 0.19665216 | L36: 0.22104156 | M36: =IF(OR(C36="",D36=""),"",D36/C36) -> 0.17431852 | N36: =IF(OR(D36="",E36=""),"",D36/E36) -> 0.13076116 | O36: =IF(OR(I36="",H36=""),"",I36/H36) -> 0.19036812
A37: Wipro | B37: 44651 | C37: 79312 | D37: 12229.6 | E37: 107275.6 | F37: 1096.4 | G37: 64306.6 | H37: 65403 | I37: 17592.9 | J37: 11.154222 | K37: 0.18698836 | L37: 0.21130407 | M37: =IF(OR(C37="",D37=""),"",D37/C37) -> 0.15419609 | N37: =IF(OR(D37="",E37=""),"",D37/E37) -> 0.11400169 | O37: =IF(OR(I37="",H37=""),"",I37/H37) -> 0.26899225
A38: Wipro | B38: 45016 | C38: 90487.6 | D38: 11350 | E38: 116923.7 | F38: 1097.6 | G38: 76570.3 | H38: 77667.9 | I38: 17466.6 | J38: 10.340932 | K38: 0.14613502 | L38: 0.17709947 | M38: =IF(OR(C38="",D38=""),"",D38/C38) -> 0.12543155 | N38: =IF(OR(D38="",E38=""),"",D38/E38) -> 0.097071851 | O38: =IF(OR(I38="",H38=""),"",I38/H38) -> 0.22488827
A39: Wipro | B39: 45382 | C39: 89760.3 | D39: 11045.2 | E39: 114608.9 | F39: 1045 | G39: 73488 | H39: 74533 | I39: 16464.9 | J39: 10.569266 | K39: 0.14819208 | L39: 0.1716649 | M39: =IF(OR(C39="",D39=""),"",D39/C39) -> 0.12305217 | N39: =IF(OR(D39="",E39=""),"",D39/E39) -> 0.096372969 | O39: =IF(OR(I39="",H39=""),"",I39/H39) -> 0.22090752
A40: Wipro | B40: 45747 | C40: 89088.4 | D40: 13135.4 | E40: 127929.1 | F40: 2094.4 | G40: 80269.7 | H40: 82364.1 | I40: 19203.5 | J40: 12.543234 | K40: 0.15947968 | L40: 0.19705191 | M40: =IF(OR(C40="",D40=""),"",D40/C40) -> 0.14744232 | N40: =IF(OR(D40="",E40=""),"",D40/E40) -> 0.10267719 | O40: =IF(OR(I40="",H40=""),"",I40/H40) -> 0.23315376
...

Sheet TCS
A1: COMPANY NAME | B1: TATA CONSULTANCY SERVICES LTD | E1: =IF(B2<>B3, "A NEW VERSION OF THE WORKSHEET IS AVAILABLE", "")
A2: LATEST VERSION | B2: 2.1 | E2: PLEASE DO NOT MAKE ANY CHANGES TO THIS SHEET
A3: CURRENT VERSION | B3: 2.1
A5: META
A6: Number of shares | B6: =IF(B9>0, B9/B8, 0) -> 361.80875
A7: Face Value | B7: 1
A8: Current Price | B8: 2093.5
A9: Market Capitalization | B9: 757446.62
A15: PROFIT & LOSS
A16: Report Date | B16: 42825 | C16: 43190 | D16: 43555 | E16: 43921 | F16: 44286 | G16: 44651 | H16: 45016 | I16: 45382 | J16: 45747 | K16: 46112
A17: Sales | B17: 117966 | C17: 123104 | D17: 146463 | E17: 156949 | F17: 164177 | G17: 191754 | H17: 225458 | I17: 240893 | J17: 255324 | K17: 267021
A18: Raw Material Cost | B18: 94 | C18: 86 | D18: 40 | E18: 18 | F18: 14 | G18: 29 | H18: 37 | I18: 42 | J18: 49 | K18: 43
A19: Change in Inventory | B19: 1
A20: Power and Fuel
A21: Other Mfr. Exp | B21: 2715 | C21: 2614 | D21: 2230 | E21: 1887 | F21: 1448 | G21: 1134 | H21: 1844 | I21: 3660 | J21: 11599 | K21: 4356
A22: Employee Cost | B22: 61621 | C22: 66396 | D22: 78246 | E22: 85952 | F22: 91814 | G22: 107554 | H22: 127522 | I22: 140131 | J22: 145788 | K22: 154994
A23: Selling and admin | B23: 16392 | C23: 16808 | D23: 20387 | E23: 20527 | F23: 18322 | G23: 23187 | H23: 28913 | I23: 24151 | J23: 20729 | K23: 24434
A24: Other Expenses | B24: 4834 | C24: 4684 | D24: 6054 | E24: 6456 | F24: 6033 | G24: 6793 | H24: 7883 | I24: 8613 | J24: 9752 | K24: 10796
A25: Other Income | B25: 4221 | C25: 3642 | D25: 4311 | E25: 4592 | F25: 1916 | G25: 4018 | H25: 3449 | I25: 3464 | J25: 3962 | K25: -124
A26: Depreciation | B26: 1987 | C26: 2014 | D26: 2056 | E26: 3529 | F26: 4065 | G26: 4604 | H26: 5022 | I26: 4985 | J26: 5242 | K26: 5560
A27: Interest | B27: 32 | C27: 52 | D27: 198 | E27: 924 | F27: 637 | G27: 784 | H27: 779 | I27: 778 | J27: 796 | K27: 1227
A28: Profit before tax | B28: 34513 | C28: 34092 | D28: 41563 | E28: 42248 | F28: 43760 | G28: 51687 | H28: 56907 | I28: 61997 | J28: 65331 | K28: 65487
A29: Tax | B29: 8156 | C29: 8212 | D29: 10001 | E29: 9801 | F29: 11198 | G29: 13238 | H29: 14604 | I29: 15898 | J29: 16534 | K29: 16033
A30: Net profit | B30: 26289 | C30: 25826 | D30: 31472 | E30: 32340 | F30: 32430 | G30: 38327 | H30: 42147 | I30: 45908 | J30: 48553 | K30: 49210
A31: Dividend Amount | B31: 9259 | C31: 9550 | D31: 11250 | E31: 27375 | F31: 14060 | G31: 15738 | H31: 42090 | I31: 26426 | J31: 45612 | K31: 39820
A32: EPS | B32: 66.708112 | C32: 67.455467 | D32: 83.871655 | E32: 86.184842 | F32: 87.669974 | G32: 104.74434 | H32: 115.18406 | I32: 126.88428 | J32: 134.19474 | K32: 136.01061
A40: Quarters
A41: Report Date | B41: 45291 | C41: 45382 | D41: 45473 | E41: 45565 | F41: 45657 | G41: 45747 | H41: 45838 | I41: 45930 | J41: 46022 | K41: 46112
A42: Sales | B42: 60583 | C42: 61237 | D42: 62613 | E42: 64259 | F42: =TechM!B61 -> 26057 | G42: 64479 | H42: 63437 | I42: 65799 | J42: 67087 | K42: 70698
A43: Expenses | B43: 44195 | C43: 44073 | D43: 45951 | E43: 47528 | F43: =TechM!C61 -> 30431.4 | G43: 47499 | H43: 46562 | I43: 47821 | J43: 48818 | K43: 51422
A44: Other Income | B44: -96 | C44: 1157 | D44: 962 | E44: 729 | F44: =TechM!D61 -> 33445.8 | G44: 1028 | H44: 1660 | I44: -268 | J44: -2273 | K44: 757
A45: Depreciation | B45: 1233 | C45: 1246 | D45: 1220 | E45: 1266 | F45: =TechM!E61 -> 37317.9 | G45: 1379 | H45: 1361 | I45: 1413 | J45: 1380 | K45: 1406
A46: Interest | B46: 230 | C46: 226 | D46: 173 | E46: 162 | F46: =TechM!F61 -> 39601.9 | G46: 227 | H46: 195 | I46: 229 | J46: 538 | K46: 265
A47: Profit before tax | B47: 14829 | C47: 16849 | D47: 16231 | E47: 16032 | F47: =TechM!G61 -> 44415.5 | G47: 16402 | H47: 16979 | I47: 16068 | J47: 14078 | K47: 18362
A48: Tax | B48: 3732 | C48: 4347 | D48: 4126 | E48: 4077 | F48: =TechM!H61 -> 45827.2 | G48: 4109 | H48: 4160 | I48: 3937 | J48: 3358 | K48: 4578
A49: Net profit | B49: 11058 | C49: 12434 | D49: 12040 | E49: 11909 | F49: =TechM!I61 -> 43149.1 | G49: 12224 | H49: 12760 | I49: 12075 | J49: 10657 | K49: 13718
A50: Operating Profit | B50: 16388 | C50: 17164 | D50: 16662 | E50: 16731 | F50: =TechM!J61 -> 44266.6 | G50: 16980 | H50: 16875 | I50: 17978 | J50: 18269 | K50: 19276
F51: =TechM!K61 -> 49167.7
A55: BALANCE SHEET
A56: Report Date | B56: 42825 | C56: 43190 | D56: 43555 | E56: 43921 | F56: 44286 | G56: 44651 | H56: 45016 | I56: 45382 | J56: 45747 | K56: 46112
...

Sheet Infosys
A1: COMPANY NAME | B1: INFOSYS LTD | E1: =IF(B2<>B3, "A NEW VERSION OF THE WORKSHEET IS AVAILABLE", "")
A2: LATEST VERSION | B2: 2.1 | E2: PLEASE DO NOT MAKE ANY CHANGES TO THIS SHEET
A3: CURRENT VERSION | B3: 2.1
A5: META
A6: Number of shares | B6: =IF(B9>0, B9/B8, 0) -> 405.75789
A7: Face Value | B7: 5
A8: Current Price | B8: 1047.2
A9: Market Capitalization | B9: 424909.66
A15: PROFIT & LOSS
A16: Report Date | B16: 42825 | C16: 43190 | D16: 43555 | E16: 43921 | F16: 44286 | G16: 44651 | H16: 45016 | I16: 45382 | J16: 45747 | K16: 46112
A17: Sales | B17: 68484 | C17: 70522 | D17: 82675 | E17: 90791 | F17: 100472 | G17: 121641 | H17: 146767 | I17: 153670 | J17: 162990 | K17: 178650
A18: Raw Material Cost
A19: Change in Inventory
A20: Power and Fuel | B20: 228 | C20: 207 | D20: 221 | E20: 229 | F20: 143 | G20: 132 | H20: 176 | I20: 199 | J20: 222 | K20: 223
A21: Other Mfr. Exp | B21: 6712 | C21: 7286 | D21: 9902 | E21: 11086 | F21: 12800 | G21: 20690 | H21: 26330 | I21: 27195 | J21: 30395 | K21: 32922
A22: Employee Cost | B22: 37669 | C22: 38902 | D22: 45323 | E22: 50895 | F22: 55547 | G22: 63997 | H22: 78374 | I22: 82636 | J22: 85968 | K22: 95112
A23: Selling and admin | B23: 4584 | C23: 4585 | D23: 5553 | E23: 5375 | F23: 3194 | G23: 4305 | H23: 5300 | I23: 5705 | J23: 6039 | K23: 6784
A24: Other Expenses | B24: 687 | C24: 720 | D24: 1506 | E24: 939 | F24: 899 | G24: 1026 | H24: 1457 | I24: 1510 | J24: 1130 | K24: 1329
A25: Other Income | B25: 3050 | C25: 3311 | D25: 2882 | E25: 2803 | F25: 2201 | G25: 2295 | H25: 2701 | I25: 4711 | J25: 3600 | K25: 3033
A26: Depreciation | B26: 1703 | C26: 1863 | D26: 2011 | E26: 2893 | F26: 3267 | G26: 3476 | H26: 4225 | I26: 4678 | J26: 4812 | K26: 4902
A27: Interest | E27: 170 | F27: 195 | G27: 200 | H27: 284 | I27: 470 | J27: 416 | K27: 416
A28: Profit before tax | B28: 19951 | C28: 20270 | D28: 21041 | E28: 22007 | F28: 26628 | G28: 30110 | H28: 33322 | I28: 35988 | J28: 37608 | K28: 39995
A29: Tax | B29: 5598 | C29: 4241 | D29: 5631 | E29: 5368 | F29: 7205 | G29: 7964 | H29: 9214 | I29: 9740 | J29: 10858 | K29: 10521
A30: Net profit | B30: 14353 | C30: 16029 | D30: 15404 | E30: 16594 | F30: 19351 | G30: 22110 | H30: 24095 | I30: 26233 | J30: 26713 | K30: 29440
A31: Dividend Amount | B31: 5891.6 | C31: 9465.6 | D31: 9222.5 | E31: 7427 | F31: 11469.6 | G31: 13007.6 | H31: 14069.2 | I31: 19053.2 | J31: 17827.8 | K31: 19430.4
A32: EPS | B32: 31.243606 | C32: 36.694748 | D32: 35.258303 | E32: 38.962198 | F32: 45.41742 | G32: 52.559013 | H32: 58.079834 | I32: 63.198343 | J32: 64.317531 | K32: 72.590985
A40: Quarters
A41: Report Date | B41: 45291 | C41: 45382 | D41: 45473 | E41: 45565 | F41: 45657 | G41: 45747 | H41: 45838 | I41: 45930 | J41: 46022 | K41: 46112
A42: Sales | B42: 38821 | C42: 37923 | D42: 39315 | E42: 40986 | F42: 41764 | G42: 40925 | H42: 42279 | I42: 44490 | J42: 45479 | K42: 46402
A43: Expenses | B43: 29684 | C43: 29139 | D43: 29878 | E43: 31177 | F43: 31649 | G43: 31051 | H43: 32336 | I43: 33955 | J43: 34845 | K43: 35235
A44: Other Income | B44: 789 | C44: 2729 | D44: 838 | E44: 712 | F44: 859 | G44: 1190 | H44: 1042 | I44: 982 | J44: -150 | K44: 1159
A45: Depreciation | B45: 1176 | C45: 1163 | D45: 1149 | E45: 1160 | F45: 1203 | G45: 1299 | H45: 1140 | I45: 1182 | J45: 1155 | K45: 1424
A46: Interest | B46: 131 | C46: 110 | D46: 105 | E46: 108 | F46: 101 | G46: 102 | H46: 105 | I46: 106 | J46: 100 | K46: 105
A47: Profit before tax | B47: 8619 | C47: 10240 | D47: 9021 | E47: 9253 | F47: 9670 | G47: 9663 | H47: 9740 | I47: 10229 | J47: 9229 | K47: 10797
A48: Tax | B48: 2506 | C48: 2265 | D48: 2647 | E48: 2737 | F48: 2848 | G48: 2625 | H48: 2816 | I48: 2854 | J48: 2563 | K48: 2288
A49: Net profit | B49: 6106 | C49: 7969 | D49: 6368 | E49: 6506 | F49: 6806 | G49: 7033 | H49: 6921 | I49: 7364 | J49: 6654 | K49: 8501
A50: Operating Profit | B50: 9137 | C50: 8784 | D50: 9437 | E50: 9809 | F50: 10115 | G50: 9874 | H50: 9943 | I50: 10535 | J50: 10634 | K50: 11167
A55: BALANCE SHEET
A56: Report Date | B56: 42825 | C56: 43190 | D56: 43555 | E56: 43921 | F56: 44286 | G56: 44651 | H56: 45016 | I56: 45382 | J56: 45747 | K56: 46112
A57: Equity Share Capital | B57: 1144 | C57: 1088 | D57: 2170 | E57: 2122 | F57: 2124 | G57: 2098 | H57: 2069 | I57: 2071 | J57: 2073 | K57: 2024
...

Sheet HCLTech
A1: COMPANY NAME | B1: HCL TECHNOLOGIES LTD | E1: =IF(B2<>B3, "A NEW VERSION OF THE WORKSHEET IS AVAILABLE", "")
A2: LATEST VERSION | B2: 2.1 | E2: PLEASE DO NOT MAKE ANY CHANGES TO THIS SHEET
A3: CURRENT VERSION | B3: 2.1
A5: META
A6: Number of shares | B6: =IF(B9>0, B9/B8, 0) -> 271.36651
A7: Face Value | B7: 2
A8: Current Price | B8: 1139
A9: Market Capitalization | B9: 309086.45
A15: PROFIT & LOSS
A16: Report Date | B16: 42825 | C16: 43190 | D16: 43555 | E16: 43921 | F16: 44286 | G16: 44651 | H16: 45016 | I16: 45382 | J16: 45747 | K16: 46112
A17: Sales | B17: 47568 | C17: 50569 | D17: 60427 | E17: 70676 | F17: 75379 | G17: 85651 | H17: 101456 | I17: 109913 | J17: 117055 | K17: 130144
A18: Raw Material Cost | B18: 826 | C18: 1251 | D18: 1615 | E18: 1536 | F18: 1698 | G18: 1473 | H18: 2072 | I18: 1754 | J18: 1976 | K18: 2715
A19: Change in Inventory | B19: 11 | C19: -104 | D19: -81 | F19: 3 | G19: 67 | H19: 67 | I19: -43 | J19: -52 | K19: 106
A20: Power and Fuel | B20: 307 | C20: 313 | D20: 336 | E20: 307 | F20: 275 | G20: 291 | H20: 328 | I20: 360 | J20: 355
A21: Other Mfr. Exp | B21: 9286 | C21: 9388 | D21: 10862 | E21: 12324 | F21: 12084 | G21: 14574 | H21: 17303 | I21: 15651 | J21: 16276
A22: Employee Cost | B22: 22866 | C22: 24729 | D22: 29283 | E22: 34928 | F22: 38853 | G22: 46130 | H22: 55280 | I22: 62480 | J22: 66755 | K22: 74143
A23: Selling and admin | B23: 2988 | C23: 2810 | D23: 3519 | E23: 3050 | F23: 1681 | G23: 1866 | H23: 2687 | I23: 3858 | J23: 4504
A24: Other Expenses | B24: 916 | C24: 728 | D24: 805 | E24: 1215 | F24: 743 | G24: 855 | H24: 1225 | I24: 1569 | J24: 1633 | K24: 26640
A25: Other Income | B25: 1069 | C25: 1230 | D25: 943 | E25: 589 | F25: 927 | G25: 1067 | H25: 1358 | I25: 1495 | J25: 2485 | K25: 574
A26: Depreciation | B26: 828 | C26: 1383 | D26: 2073 | E26: 3420 | F26: 4611 | G26: 4326 | H26: 4145 | I26: 4173 | J26: 4084 | K26: 4355
A27: Interest | B27: 89 | C27: 69 | D27: 174 | E27: 505 | F27: 511 | G27: 319 | H27: 353 | I27: 553 | J27: 644 | K27: 869
A28: Profit before tax | B28: 10542 | C28: 11024 | D28: 12622 | E28: 13980 | F28: 15853 | G28: 16951 | H28: 19488 | I28: 20967 | J28: 23261 | K28: 22102
A29: Tax | B29: 1936 | C29: 2302 | D29: 2502 | E29: 2923 | F29: 4684 | G29: 3428 | H29: 4643 | I29: 5257 | J29: 5862 | K29: 5450
A30: Net profit | B30: 8606 | C30: 8721 | D30: 10120 | E30: 11057 | F30: 11145 | G30: 13499 | H30: 14851 | I30: 15702 | J30: 17390 | K30: 16642
A31: Dividend Amount | B31: 3420 | C31: 1668 | D31: 1084 | E31: 2715 | F31: 2715 | G31: 11403 | H31: 13032 | I31: 14118 | J31: 16290 | K31: 14661
